[2025-10-21 16:22:00] 错误 - 模块导入失败: 错误: 无法导入应用模块: No module named 'utils.tool_localization' | 上下文: {"exception_type": "ModuleNotFoundError", "traceback": "Traceback (most recent call last):\n  File \"C:\\Users\\15052\\Desktop\\BioNexus\\BioNexus_1.2.23\\main.py\", line 151, in <module>\n    from ui.main_window import MainWindow\n  File \"C:\\Users\\15052\\Desktop\\BioNexus\\BioNexus_1.2.23\\ui\\main_window.py\", line 38, in <module>\n    from core.tool_manager import ToolManager\n  File \"C:\\Users\\15052\\Desktop\\BioNexus\\BioNexus_1.2.23\\core\\tool_manager.py\", line 17, in <module>\n    from utils.tool_localization import get_localized_tool_description\nModuleNotFoundError: No module named 'utils.tool_localization'\n"}
2025-10-21 16:22:00,323 - ERROR - 错误 - 模块导入失败: 错误: 无法导入应用模块: No module named 'utils.tool_localization' | 上下文: {"exception_type": "ModuleNotFoundError", "traceback": "Traceback (most recent call last):\n  File \"C:\\Users\\15052\\Desktop\\BioNexus\\BioNexus_1.2.23\\main.py\", line 151, in <module>\n    from ui.main_window import MainWindow\n  File \"C:\\Users\\15052\\Desktop\\BioNexus\\BioNexus_1.2.23\\ui\\main_window.py\", line 38, in <module>\n    from core.tool_manager import ToolManager\n  File \"C:\\Users\\15052\\Desktop\\BioNexus\\BioNexus_1.2.23\\core\\tool_manager.py\", line 17, in <module>\n    from utils.tool_localization import get_localized_tool_description\nModuleNotFoundError: No module named 'utils.tool_localization'\n"}
